<?xml version="1.0" ?>
<testsuite errors="1" failures="1" name="tuqquery.n1ql_fts_integration.N1qlFTSIntegrationTest" skip="0" tests="1" time="692.528254986">
	<testcase name="tuqquery.n1ql_fts_integration.N1qlFTSIntegrationTest.test_mixed_cluster,doc-per-day:1,GROUP:P1,spec:test,reset_services:True,num_nodes:3,cluster_name:test,services_init:kv:index:n1ql-kv-index:n1ql:fts,conf_file:test.conf,case_number:1,get-logs:False,stop-on-failure:False,scan_consistency:NOT_BOUNDED,logs_folder:/Users/girishbenakappa/IdeaProjects/testrunner/logs/testrunner-19-Aug-12_13-46-42/test_1,bucket_size:200,nodes_init:3,ini:test.ini" time="692.528254986">
		<error type="membase.error">['Traceback (most recent call last):\n  File &quot;pytests/tuqquery/n1ql_fts_integration.py&quot;, line 268, in setUp\n    super(N1qlFTSIntegrationTest, self).setUp()\n  File &quot;pytests/tuqquery/tuq.py&quot;, line 48, in setUp\n    super(QueryTests, self).setUp()\n  File &quot;pytests/basetestcase.py&quot;, line 385, in setUp\n    self.fail(e)\nAssertionError: unable to reach the host @ 192.168.10.13\n']</error>
	</testcase>
</testsuite>
