<?xml version="1.0" ?>
<testsuite errors="1" failures="1" name="fts.stable_topology_fts.StableTopFTS" skip="0" tests="1" time="147.050631046">
	<testcase name="fts.stable_topology_fts.StableTopFTS.run_default_index_query,GROUP:P0,items:1000,upd:100,expected_hits:1000,update:True,conf_file:test.conf,num_nodes:3,cluster_name:test,expected_no_of_results:1000,ini:test.ini,case_number:1,query:&quot;&quot;&quot;{&quot;min&quot;: 1, &quot;max&quot;:1, &quot;field&quot;: &quot;mutated&quot;, &quot;inclusive_min&quot;: true, &quot;inclusive_max&quot;: true}&quot;&quot;&quot;,logs_folder:/Users/girishbenakappa/IdeaProjects/testrunner/logs/testrunner-19-Apr-26_21-51-35/test_1,spec:test" time="147.050631046">
		<error type="membase.error">['Traceback (most recent call last):\n  File &quot;pytests/fts/stable_topology_fts.py&quot;, line 88, in run_default_index_query\n    expected_no_of_results=expected_no_of_results)\n  File &quot;pytests/fts/fts_base.py&quot;, line 1176, in execute_query\n    % (expected_no_of_results, doc_ids.__len__()))\nFTSException: Expected number of results: 1000, fts returned: 10\n']</error>
	</testcase>
</testsuite>
