<?xml version="1.0" ?>
<testsuite errors="2" failures="2" name="tuqquery.flex_index_phase1.FlexIndexTests" skip="0" tests="2" time="71.87648177146912">
	<testcase name="tuqquery.flex_index_phase1.FlexIndexTests.test_flex_single_typemapping,scan_consistency:NOT_BOUNDED,skip_load:True,items:1000,bucket_size:200,cluster:D,D+F,F,index_type:scorch,fts_quota:750,custom_map_add_non_indexed_fields:False,text_analyzer:keyword,use_index_name_in_query:False,flex_query_option:flex_use_fts_gsi_query,custom_map:True,ini:test.ini,cluster_name:test,spec:test,conf_file:test.conf,get-cbcollect-info:False,get-logs:False,stop-on-failure:False,num_nodes:4,case_number:1,logs_folder:/Users/girishbenakappa/IdeaProjects/testrunner/logs/testrunner-20-May-05_13-20-42/test_1" time="48.1720769405365">
		<error type="membase.error">['Traceback (most recent call last):\n  File &quot;pytests/basetestcase.py&quot;, line 232, in setUp\n    self._cluster_cleanup()\n  File &quot;pytests/basetestcase.py&quot;, line 589, in _cluster_cleanup\n    ClusterOperationHelper.cleanup_cluster(self.servers, master=self.master)\n  File &quot;lib/membase/helper/cluster_helper.py&quot;, line 267, in cleanup_cluster\n    wait_for_rebalance=wait_for_rebalance)\nmembase.api.exception.RebalanceFailedException: Rebalance Failed: {\'status\': \'none\', \'errorMessage\': \'Rebalance failed. See logs for detailed reason. You can try again.\'} - rebalance failed\n\nDuring handling of the above exception, another exception occurred:\n\nTraceback (most recent call last):\n  File &quot;pytests/tuqquery/flex_index_phase1.py&quot;, line 20, in setUp\n    super(FlexIndexTests, self).setUp()\n  File &quot;pytests/tuqquery/tuq.py&quot;, line 50, in setUp\n    super(QueryTests, self).setUp()\n  File &quot;pytests/basetestcase.py&quot;, line 422, in setUp\n    self.fail(e)\nAssertionError: Rebalance Failed: {\'status\': \'none\', \'errorMessage\': \'Rebalance failed. See logs for detailed reason. You can try again.\'} - rebalance failed\n']</error>
	</testcase>
	<testcase name="tuqquery.flex_index_phase1.FlexIndexTests.test_flex_multi_typemapping,scan_consistency:NOT_BOUNDED,skip_load:True,items:1000,bucket_size:200,cluster:D,D+F,F,index_type:scorch,fts_quota:750,custom_map_add_non_indexed_fields:False,text_analyzer:keyword,use_index_name_in_query:True,flex_query_option:flex_use_fts_query,nodes_init:3,custom_map:True,flex_dataset:all,doc_maps:2,ini:test.ini,cluster_name:test,spec:test,conf_file:test.conf,get-cbcollect-info:False,get-logs:False,stop-on-failure:False,num_nodes:4,case_number:2,logs_folder:/Users/girishbenakappa/IdeaProjects/testrunner/logs/testrunner-20-May-05_13-20-42/test_2" time="23.704404830932617">
		<error type="membase.error">['Traceback (most recent call last):\n  File &quot;pytests/basetestcase.py&quot;, line 232, in setUp\n    self._cluster_cleanup()\n  File &quot;pytests/basetestcase.py&quot;, line 589, in _cluster_cleanup\n    ClusterOperationHelper.cleanup_cluster(self.servers, master=self.master)\n  File &quot;lib/membase/helper/cluster_helper.py&quot;, line 267, in cleanup_cluster\n    wait_for_rebalance=wait_for_rebalance)\nmembase.api.exception.RebalanceFailedException: Rebalance Failed: {\'status\': \'none\', \'errorMessage\': \'Rebalance failed. See logs for detailed reason. You can try again.\'} - rebalance failed\n\nDuring handling of the above exception, another exception occurred:\n\nTraceback (most recent call last):\n  File &quot;pytests/tuqquery/flex_index_phase1.py&quot;, line 20, in setUp\n    super(FlexIndexTests, self).setUp()\n  File &quot;pytests/tuqquery/tuq.py&quot;, line 50, in setUp\n    super(QueryTests, self).setUp()\n  File &quot;pytests/basetestcase.py&quot;, line 422, in setUp\n    self.fail(e)\nAssertionError: Rebalance Failed: {\'status\': \'none\', \'errorMessage\': \'Rebalance failed. See logs for detailed reason. You can try again.\'} - rebalance failed\n']</error>
	</testcase>
</testsuite>
