<?xml version="1.0" ?>
<testsuite errors="1" failures="1" name="fts.stable_topology_fts.StableTopFTS" skip="0" tests="1" time="145.837640047">
	<testcase name="fts.stable_topology_fts.StableTopFTS.index_query_custom_mapping,doc-per-day:1,GROUP:P1,compare_es:True,num_queries:100,fts_quota:750,cluster:D+F,stop-on-failure:False,ini:test.ini,case_number:1,get-logs:False,logs_folder:/Users/girishbenakappa/IdeaProjects/testrunner/logs/testrunner-19-Aug-13_14-25-36/test_1,custom_map:True,cluster_name:test,num_custom_analyzers:1,cm_id:35,items:1000,spec:test,conf_file:test.conf,num_nodes:2,multiple_filters:true,index_type:scorch,scan_consistency:NOT_BOUNDED,get-cbcollect-info:False,bucket_size:200,disable_HTP:True" time="145.837640047">
		<error type="membase.error">['Traceback (most recent call last):\n  File &quot;pytests/fts/stable_topology_fts.py&quot;, line 565, in index_query_custom_mapping\n    self.run_query_and_compare(index, n1ql_executor=n1ql_executor)\n  File &quot;pytests/fts/fts_base.py&quot;, line 4317, in run_query_and_compare\n    failed_queries))\nAssertionError: 1 out of 100 queries failed! - [53]\n']</error>
	</testcase>
</testsuite>
