<?xml version="1.0" ?>
<testsuite errors="1" failures="1" name="tuqquery.flex_index_phase1.FlexIndexTests" skip="0" tests="1" time="179.85733795166016">
	<testcase name="tuqquery.flex_index_phase1.FlexIndexTests.test_flex_multi_typemapping,scan_consistency:NOT_BOUNDED,skip_load:True,items:1000,bucket_size:200,cluster:D,D+F,F,index_type:scorch,fts_quota:750,custom_map_add_non_indexed_fields:False,text_analyzer:keyword,use_index_name_in_query:True,flex_query_option:flex_use_fts_query,cm_id:3,nodes_init:3,custom_map:True,dataset:all,ini:test.ini,cluster_name:test,spec:test,conf_file:test.conf,get-cbcollect-info:False,get-logs:False,stop-on-failure:False,num_nodes:3,case_number:1,logs_folder:/Users/girishbenakappa/IdeaProjects/testrunner/logs/testrunner-20-May-04_11-47-44/test_1" time="179.85733795166016">
		<error type="membase.error">['Traceback (most recent call last):\n  File &quot;pytests/tuqquery/flex_index_phase1.py&quot;, line 19, in setUp\n    super(FlexIndexTests, self).setUp()\n  File &quot;pytests/tuqquery/tuq.py&quot;, line 90, in setUp\n    self.gens_load = self.gen_docs(self.docs_per_day)\n  File &quot;pytests/tuqquery/tuq.py&quot;, line 789, in gen_docs\n    self.fail(&quot;There is no dataset %s, please enter a valid one&quot; % self.dataset)\nAssertionError: There is no dataset all, please enter a valid one\n']</error>
	</testcase>
</testsuite>
