<?xml version="1.0" ?>
<testsuite errors="1" failures="1" name="fts.index_management_api.IndexManagementAPI" skip="0" tests="1" time="305.387731075">
	<testcase name="fts.index_management_api.IndexManagementAPI.test_planfreeze_control,doc-per-day:1,GROUP:P1,index_type:scorch,spec:test,fts_quota:750,conf_file:test.conf,num_nodes:2,cluster_name:test,cluster:D+F+Q,stop-on-failure:False,ini:test.ini,case_number:1,get-logs:False,scan_consistency:NOT_BOUNDED,logs_folder:/Users/girishbenakappa/IdeaProjects/testrunner/logs/testrunner-19-Aug-20_17-15-52/test_1,bucket_size:200,disable_HTP:True" time="305.387731075">
		<error type="membase.error">['Traceback (most recent call last):\n  File &quot;pytests/fts/index_management_api.py&quot;, line 58, in test_planfreeze_control\n    index_count_after_freeze = fts_index.get_indexed_doc_count()\n  File &quot;pytests/fts/fts_base.py&quot;, line 1008, in get_indexed_doc_count\n    return rest.get_fts_index_doc_count(self.name)\n  File &quot;lib/membase/api/rest_client.py&quot;, line 2866, in get_fts_index_doc_count\n    return json_parsed[\'count\']\nKeyError: \'count\'\n']</error>
	</testcase>
</testsuite>
