<?xml version="1.0" ?>
<testsuite errors="1" failures="1" name="fts.moving_topology_fts.MovingTopFTS" skip="0" tests="1" time="2.797701120376587">
	<testcase name="fts.moving_topology_fts.MovingTopFTS.rebalance_in_during_index_building,items:100000,cluster:D,F,GROUP:P0,get-cbcollect-info:False,disable_HTP:True,get-logs:False,stop-on-failure:False,index_type:scorch,fts_quota:750,ini:test.ini,cluster_name:test,spec:test,conf_file:test.conf,num_nodes:1,case_number:1,logs_folder:/Users/girishbenakappa/IdeaProjects/testrunner/logs/testrunner-20-Apr-24_10-46-24/test_1" time="2.797701120376587">
		<error type="membase.error">['Traceback (most recent call last):\n  File &quot;pytests/fts/moving_topology_fts.py&quot;, line 17, in setUp\n    super(MovingTopFTS, self).setUp()\n  File &quot;pytests/fts/fts_base.py&quot;, line 3119, in setUp\n    self.__setup_for_test()\n  File &quot;pytests/fts/fts_base.py&quot;, line 3282, in __setup_for_test\n    self._input.servers[1:])\n  File &quot;pytests/fts/fts_base.py&quot;, line 1870, in init_cluster\n    % (len(available_nodes) + 1, cluster_services))\nlib.membase.api.exception.FTSException: Only 1 nodes present for given clusterconfiguration [\'kv\', \'fts\']\n']</error>
	</testcase>
</testsuite>
