<?xml version="1.0" ?>
<testsuite errors="1" failures="1" name="fts.index_management_api.IndexManagementAPI" skip="0" tests="2" time="708.257236004">
	<testcase name="fts.index_management_api.IndexManagementAPI.test_index_plan_update_disallow_query,doc-per-day:1,GROUP:P1,index_type:scorch,spec:test,fts_quota:750,conf_file:test.conf,num_nodes:4,cluster_name:test,cluster:D+F,stop-on-failure:False,ini:test.ini,case_number:1,get-logs:False,scan_consistency:NOT_BOUNDED,logs_folder:/Users/girishbenakappa/IdeaProjects/testrunner/logs/testrunner-19-Aug-14_15-46-01/test_1,bucket_size:200,disable_HTP:True" time="452.538019896"/>
	<testcase name="fts.index_management_api.IndexManagementAPI.test_query_index_freeze_plan,doc-per-day:1,GROUP:P1,index_type:scorch,spec:test,fts_quota:750,conf_file:test.conf,num_nodes:4,cluster_name:test,cluster:D+F,stop-on-failure:False,ini:test.ini,case_number:2,get-logs:False,scan_consistency:NOT_BOUNDED,logs_folder:/Users/girishbenakappa/IdeaProjects/testrunner/logs/testrunner-19-Aug-14_15-46-01/test_2,bucket_size:200,disable_HTP:True" time="255.719216108">
		<error type="membase.error">['Traceback (most recent call last):\n  File &quot;pytests/fts/index_management_api.py&quot;, line 161, in test_query_index_freeze_plan\n    self.validate_index_count(equal_bucket_doc_count=True)\n  File &quot;pytests/fts/fts_base.py&quot;, line 4021, in validate_index_count\n    docs_indexed = index.get_indexed_doc_count()\n  File &quot;pytests/fts/fts_base.py&quot;, line 1008, in get_indexed_doc_count\n    return rest.get_fts_index_doc_count(self.name)\n  File &quot;lib/membase/api/rest_client.py&quot;, line 2866, in get_fts_index_doc_count\n    return json_parsed[\'count\']\nKeyError: \'count\'\n']</error>
	</testcase>
</testsuite>
