<?xml version="1.0" ?>
<testsuite errors="1" failures="1" name="fts.moving_topology_fts.MovingTopFTS" skip="0" tests="1" time="153.240239859">
	<testcase name="fts.moving_topology_fts.MovingTopFTS.graceful_failover_and_full_recovery_during_index_building,get-coredumps:False,doc-per-day:1,logs_folder:/Users/girishbenakappa/IdeaProjects/testrunner/logs/testrunner-19-Sep-17_11-49-34/test_1,GROUP:P1,items:30000,spec:test,conf_file:test.conf,num_nodes:3,cluster_name:test,cluster:D,D+F,stop-on-failure:False,ini:test.ini,case_number:1,get-logs:False,scan_consistency:NOT_BOUNDED,get-cbcollect-info:False,bucket_size:200" time="153.240239859">
		<error type="membase.error">['Traceback (most recent call last):\n  File &quot;pytests/fts/moving_topology_fts.py&quot;, line 326, in graceful_failover_and_full_recovery_during_index_building\n    self._cb_cluster.add_back_node(recovery_type=\'full\', services=[&quot;kv, fts&quot;])\n  File &quot;pytests/fts/fts_base.py&quot;, line 2982, in add_back_node\n    recoveryType=recovery_type)\n  File &quot;lib/membase/api/rest_client.py&quot;, line 1459, in set_recovery_type\n    raise SetRecoveryTypeFailed(content)\nSetRecoveryTypeFailed: Set RecoveryType failed :{&quot;otpNode&quot;:&quot;invalid node name or node can\'t be used for delta recovery&quot;} \n']</error>
	</testcase>
</testsuite>
