<?xml version="1.0" ?>
<testsuite errors="4" failures="4" name="tuqquery.flex_index_phase1.FlexIndexTests" skip="0" tests="4" time="118.88495588302612">
	<testcase name="tuqquery.flex_index_phase1.FlexIndexTests.test_flex_single_typemapping_comp_ops,test_name:fts_index_exists,GROUP:PS,get-logs:False,stop-on-failure:False,doc-per-day:6,bucket_size:200,scan_consistency:NOT_BOUNDED,skip_load:True,items:1000,custom_map:True,get-cbcollect-info:False,disable_HTP:True,cluster:D+F,index_type:scorch,fts_quota:750,custom_map_add_non_indexed_fields:False,text_analyzer:keyword,cm_id:1,ini:test.ini,cluster_name:test,spec:test,conf_file:test.conf,num_nodes:1,case_number:1,logs_folder:/Users/girishbenakappa/IdeaProjects/testrunner/logs/testrunner-20-Apr-23_11-44-29/test_1" time="53.39308786392212">
		<error type="membase.error">['Traceback (most recent call last):\n  File &quot;pytests/tuqquery/flex_index_phase1.py&quot;, line 204, in test_flex_single_typemapping_comp_ops\n    .format(failed_to_run_query, not_found_index_in_response, result_mismatch))\nAssertionError: Found queries not runnable: [] or required index not found in the query resonse: [7, 20, 21, 22, 23, 24] or flex query and gsi query results not matching: [15, 16, 18, 19, 25, 26, 27, 28, 29, 37]\n']</error>
	</testcase>
	<testcase name="tuqquery.flex_index_phase1.FlexIndexTests.test_flex_single_typemapping_comp_ops,test_name:fts_index_exists,GROUP:PS,get-logs:False,stop-on-failure:False,doc-per-day:6,bucket_size:200,scan_consistency:NOT_BOUNDED,skip_load:True,items:1000,custom_map:True,get-cbcollect-info:False,disable_HTP:True,cluster:D+F,index_type:scorch,fts_quota:750,custom_map_add_non_indexed_fields:False,text_analyzer:keyword,cm_id:2,ini:test.ini,cluster_name:test,spec:test,conf_file:test.conf,num_nodes:1,case_number:2,logs_folder:/Users/girishbenakappa/IdeaProjects/testrunner/logs/testrunner-20-Apr-23_11-44-29/test_2" time="22.026676177978516">
		<error type="membase.error">['Traceback (most recent call last):\n  File &quot;pytests/tuqquery/flex_index_phase1.py&quot;, line 204, in test_flex_single_typemapping_comp_ops\n    .format(failed_to_run_query, not_found_index_in_response, result_mismatch))\nAssertionError: Found queries not runnable: [] or required index not found in the query resonse: [] or flex query and gsi query results not matching: [6, 7, 8, 9, 11, 13, 15, 16, 17, 18, 19]\n']</error>
	</testcase>
	<testcase name="tuqquery.flex_index_phase1.FlexIndexTests.test_flex_single_typemapping_comp_ops,test_name:fts_index_exists,GROUP:PS,get-logs:False,stop-on-failure:False,doc-per-day:6,bucket_size:200,scan_consistency:NOT_BOUNDED,skip_load:True,items:1000,custom_map:True,get-cbcollect-info:False,disable_HTP:True,cluster:D+F,index_type:scorch,fts_quota:750,custom_map_add_non_indexed_fields:False,text_analyzer:keyword,cm_id:3,ini:test.ini,cluster_name:test,spec:test,conf_file:test.conf,num_nodes:1,case_number:3,logs_folder:/Users/girishbenakappa/IdeaProjects/testrunner/logs/testrunner-20-Apr-23_11-44-29/test_3" time="21.91976499557495">
		<error type="membase.error">['Traceback (most recent call last):\n  File &quot;pytests/tuqquery/flex_index_phase1.py&quot;, line 204, in test_flex_single_typemapping_comp_ops\n    .format(failed_to_run_query, not_found_index_in_response, result_mismatch))\nAssertionError: Found queries not runnable: [] or required index not found in the query resonse: [20, 21, 22, 23, 24] or flex query and gsi query results not matching: [7, 8, 9, 10, 37, 38]\n']</error>
	</testcase>
	<testcase name="tuqquery.flex_index_phase1.FlexIndexTests.test_flex_single_typemapping_comp_ops,test_name:fts_index_exists,GROUP:PS,get-logs:False,stop-on-failure:False,doc-per-day:6,bucket_size:200,scan_consistency:NOT_BOUNDED,skip_load:True,items:1000,custom_map:True,get-cbcollect-info:False,disable_HTP:True,cluster:D+F,index_type:scorch,fts_quota:750,custom_map_add_non_indexed_fields:False,text_analyzer:keyword,cm_id:4,ini:test.ini,cluster_name:test,spec:test,conf_file:test.conf,num_nodes:1,case_number:4,logs_folder:/Users/girishbenakappa/IdeaProjects/testrunner/logs/testrunner-20-Apr-23_11-44-29/test_4" time="21.545426845550537">
		<error type="membase.error">['Traceback (most recent call last):\n  File &quot;pytests/tuqquery/flex_index_phase1.py&quot;, line 204, in test_flex_single_typemapping_comp_ops\n    .format(failed_to_run_query, not_found_index_in_response, result_mismatch))\nAssertionError: Found queries not runnable: [10, 11, 12, 13, 14] or required index not found in the query resonse: [4, 24, 25, 26, 27, 28] or flex query and gsi query results not matching: [1, 2, 3, 8, 15, 16, 17, 18, 19, 20, 21, 22, 23, 35]\n']</error>
	</testcase>
</testsuite>
