<?xml version="1.0" ?>
<testsuite errors="2" failures="2" name="fts.index_management_api.IndexManagementAPI" skip="0" tests="2" time="84.6190550327">
	<testcase name="fts.index_management_api.IndexManagementAPI.test_index_plan_update_disallow_query,doc-per-day:1,GROUP:P1,index_type:scorch,spec:test,fts_quota:750,conf_file:test.conf,num_nodes:4,cluster_name:test,cluster:D+F,stop-on-failure:False,ini:test.ini,case_number:1,get-logs:False,scan_consistency:NOT_BOUNDED,logs_folder:/Users/girishbenakappa/IdeaProjects/testrunner/logs/testrunner-19-Aug-14_13-28-29/test_1,bucket_size:200,disable_HTP:True" time="23.7706160545">
		<error type="membase.error">['Traceback (most recent call last):\n  File &quot;pytests/fts/index_management_api.py&quot;, line 11, in setUp\n    super(IndexManagementAPI, self).setUp()\n  File &quot;pytests/fts/fts_base.py&quot;, line 3105, in setUp\n    self.__setup_for_test()\n  File &quot;pytests/fts/fts_base.py&quot;, line 3254, in __setup_for_test\n    self.__create_buckets()\n  File &quot;pytests/fts/fts_base.py&quot;, line 3478, in __create_buckets\n    maxttl=maxttl)\n  File &quot;pytests/fts/fts_base.py&quot;, line 2087, in create_default_bucket\n    self.__clusterop.create_default_bucket(bucket_params)\n  File &quot;lib/couchbase_helper/cluster.py&quot;, line 273, in create_default_bucket\n    return _task.result(timeout)\n  File &quot;lib/tasks/future.py&quot;, line 160, in result\n    return self.__get_result()\n  File &quot;lib/tasks/future.py&quot;, line 112, in __get_result\n    raise self._exception\nBucketCreationException: unable to create bucket default on the host @ 172.23.109.172\n']</error>
	</testcase>
	<testcase name="fts.index_management_api.IndexManagementAPI.test_query_index_freeze_plan,doc-per-day:1,GROUP:P1,index_type:scorch,spec:test,fts_quota:750,conf_file:test.conf,num_nodes:4,cluster_name:test,cluster:D+F,stop-on-failure:False,ini:test.ini,case_number:2,get-logs:False,scan_consistency:NOT_BOUNDED,logs_folder:/Users/girishbenakappa/IdeaProjects/testrunner/logs/testrunner-19-Aug-14_13-28-29/test_2,bucket_size:200,disable_HTP:True" time="60.8484389782">
		<error type="membase.error">['Traceback (most recent call last):\n  File &quot;pytests/fts/index_management_api.py&quot;, line 11, in setUp\n    super(IndexManagementAPI, self).setUp()\n  File &quot;pytests/fts/fts_base.py&quot;, line 3105, in setUp\n    self.__setup_for_test()\n  File &quot;pytests/fts/fts_base.py&quot;, line 3254, in __setup_for_test\n    self.__create_buckets()\n  File &quot;pytests/fts/fts_base.py&quot;, line 3478, in __create_buckets\n    maxttl=maxttl)\n  File &quot;pytests/fts/fts_base.py&quot;, line 2087, in create_default_bucket\n    self.__clusterop.create_default_bucket(bucket_params)\n  File &quot;lib/couchbase_helper/cluster.py&quot;, line 273, in create_default_bucket\n    return _task.result(timeout)\n  File &quot;lib/tasks/future.py&quot;, line 160, in result\n    return self.__get_result()\n  File &quot;lib/tasks/future.py&quot;, line 112, in __get_result\n    raise self._exception\nBucketCreationException: unable to create bucket default on the host @ 172.23.109.172\n']</error>
	</testcase>
</testsuite>
