<?xml version="1.0" ?>
<testsuite errors="1" failures="1" name="fts.stable_topology_fts.StableTopFTS" skip="0" tests="1" time="7.463375091552734">
	<testcase name="fts.stable_topology_fts.StableTopFTS.test_geo_polygon_query,items:1000,fail-on-errors:False,compare_es:False,cluster:D+F+Q,num_queries:1000,get-cbcollect-info:false,get-logs:false,stop-on-failure:False,index_type:scorch,fts_quota:750,GROUP:P1,polygon_feature:irregular,run_via_n1ql:True,ini:temp-nodes.ini,cluster_name:temp-nodes,spec:test,conf_file:test.conf,index_loglevel:debug,num_nodes:4,case_number:1,logs_folder:/Users/girishbenakappa/exp-query/lat/testrunner/logs/testrunner-20-Mar-19_22-13-30/test_1" time="7.463375091552734">
		<error type="membase.error">['Traceback (most recent call last):\n  File &quot;pytests/fts/fts_base.py&quot;, line 1888, in init_cluster\n    services=node_services).result()\n  File &quot;lib/tasks/future.py&quot;, line 160, in result\n    return self.__get_result()\n  File &quot;lib/tasks/future.py&quot;, line 112, in __get_result\n    raise self._exception\n  File &quot;lib/tasks/task.py&quot;, line 653, in execute\n    self.add_nodes(task_manager)\n  File &quot;lib/tasks/task.py&quot;, line 680, in add_nodes\n    node.ip, node.port, services = services_for_node)\n  File &quot;lib/membase/api/rest_client.py&quot;, line 1434, in add_node\n    reason=content)\nmembase.api.exception.AddNodeException: Error adding node: 172.23.121.68 to the cluster:172.23.121.65 - b\'[&quot;Prepare join failed. Got HTTP status 500 from REST call post to http://172.23.121.68:8091/engageCluster2. Body was: \\\\&quot;[\\\\\\\\\\\\&quot;Unexpected server error, request logged.\\\\\\\\\\\\&quot;]\\\\&quot;&quot;]\'\n\nDuring handling of the above exception, another exception occurred:\n\nTraceback (most recent call last):\n  File &quot;pytests/fts/stable_topology_fts.py&quot;, line 21, in setUp\n    super(StableTopFTS, self).setUp()\n  File &quot;pytests/fts/fts_base.py&quot;, line 3114, in setUp\n    self.__setup_for_test()\n  File &quot;pytests/fts/fts_base.py&quot;, line 3270, in __setup_for_test\n    self._input.servers[1:])\n  File &quot;pytests/fts/fts_base.py&quot;, line 1891, in init_cluster\n    &quot;%s: %s&quot; % (cluster_services, e))\nlib.membase.api.exception.FTSException: Unable to initialize cluster with config [\'kv,fts,n1ql\']: Error adding node: 172.23.121.68 to the cluster:172.23.121.65 - b\'[&quot;Prepare join failed. Got HTTP status 500 from REST call post to http://172.23.121.68:8091/engageCluster2. Body was: \\\\&quot;[\\\\\\\\\\\\&quot;Unexpected server error, request logged.\\\\\\\\\\\\&quot;]\\\\&quot;&quot;]\'\n']</error>
	</testcase>
</testsuite>
