<?xml version="1.0" ?>
<testsuite errors="1" failures="1" name="fts.stable_topology_fts.StableTopFTS" skip="0" tests="1" time="29.5360529423">
	<testcase name="fts.stable_topology_fts.StableTopFTS.index_query_custom_mapping,doc-per-day:1,GROUP:P1,compare_es:True,num_queries:100,fts_quota:750,cluster:D+F,stop-on-failure:False,ini:test.ini,case_number:1,get-logs:False,logs_folder:/Users/girishbenakappa/IdeaProjects/testrunner/logs/testrunner-19-Aug-13_14-22-47/test_1,custom_map:True,cluster_name:test,num_custom_analyzers:1,cm_id:35,items:1000,spec:test,conf_file:test.conf,num_nodes:1,multiple_filters:true,index_type:scorch,scan_consistency:NOT_BOUNDED,get-cbcollect-info:False,bucket_size:200,disable_HTP:True" time="29.5360529423">
		<error type="membase.error">['Traceback (most recent call last):\n  File &quot;pytests/fts/stable_topology_fts.py&quot;, line 548, in index_query_custom_mapping\n    index_name=&quot;custom_index&quot;)\n  File &quot;pytests/fts/fts_base.py&quot;, line 3981, in create_index\n    plan_params=plan_params)\n  File &quot;pytests/fts/fts_base.py&quot;, line 2133, in create_fts_index\n    index.create()\n  File &quot;pytests/fts/fts_base.py&quot;, line 898, in create\n    rest = RestConnection(self.__cluster.get_random_fts_node())\n  File &quot;pytests/fts/fts_base.py&quot;, line 1779, in get_random_fts_node\n    raise FTSException(&quot;No node in the cluster has \'fts\' service&quot;\nFTSException: No node in the cluster has \'fts\' service enabled\n']</error>
	</testcase>
</testsuite>
