<?xml version="1.0" ?>
<testsuite errors="2" failures="2" name="fts.stable_topology_fts.StableTopFTS" skip="0" tests="4" time="1546.09438086">
	<testcase name="fts.stable_topology_fts.StableTopFTS.run_default_index_query,GROUP:P0,items:1000,upd:100,expected_hits:1000,update:True,conf_file:test.conf,num_nodes:3,cluster_name:test,query_limit_matches:4,expected_no_of_results:4,ini:test.ini,case_number:1,query:&quot;&quot;&quot;{&quot;min&quot;: 1, &quot;max&quot;:1, &quot;field&quot;: &quot;mutated&quot;, &quot;inclusive_min&quot;: true, &quot;inclusive_max&quot;: true}&quot;&quot;&quot;,logs_folder:/Users/girishbenakappa/IdeaProjects/testrunner/logs/testrunner-19-Apr-26_21-18-47/test_1,spec:test" time="145.66593504"/>
	<testcase name="fts.stable_topology_fts.StableTopFTS.run_default_index_query,GROUP:P0,items:1000,upd:100,expected_hits:1000,update:True,conf_file:test.conf,num_nodes:3,cluster_name:test,expected_no_of_results:8,query_max_matches:8,ini:test.ini,case_number:2,query:&quot;&quot;&quot;{&quot;min&quot;: 1, &quot;max&quot;:1, &quot;field&quot;: &quot;mutated&quot;, &quot;inclusive_min&quot;: true, &quot;inclusive_max&quot;: true}&quot;&quot;&quot;,logs_folder:/Users/girishbenakappa/IdeaProjects/testrunner/logs/testrunner-19-Apr-26_21-18-47/test_2,spec:test" time="1063.98055983">
		<error type="membase.error">['Traceback (most recent call last):\n  File &quot;pytests/fts/stable_topology_fts.py&quot;, line 24, in tearDown\n    super(StableTopFTS, self).tearDown()\n  File &quot;pytests/fts/fts_base.py&quot;, line 3071, in tearDown\n    self._cb_cluster.cleanup_cluster(self)\n  File &quot;pytests/fts/fts_base.py&quot;, line 1840, in cleanup_cluster\n    self.__stop_rebalance()\n  File &quot;pytests/fts/fts_base.py&quot;, line 1667, in __stop_rebalance\n    rest = RestConnection(self.__master_node)\n  File &quot;lib/membase/api/rest_client.py&quot;, line 335, in __init__\n    http_res, success = self.init_http_request(self.baseUrl + \'nodes/self\')\n  File &quot;lib/membase/api/rest_client.py&quot;, line 440, in init_http_request\n    headers=self._create_capi_headers())\n  File &quot;lib/membase/api/rest_client.py&quot;, line 847, in _http_request\n    raise ServerUnavailableException(ip=self.ip)\nServerUnavailableException: unable to reach the host @ 192.168.10.12\n']</error>
	</testcase>
	<testcase name="fts.stable_topology_fts.StableTopFTS.run_default_index_query,GROUP:P0,items:1000,upd:100,expected_hits:1000,update:True,conf_file:test.conf,num_nodes:3,cluster_name:test,query_limit_matches:4,expected_no_of_results:10,query_max_matches:10,ini:test.ini,case_number:3,query:&quot;&quot;&quot;{&quot;min&quot;: 1, &quot;max&quot;:1, &quot;field&quot;: &quot;mutated&quot;, &quot;inclusive_min&quot;: true, &quot;inclusive_max&quot;: true}&quot;&quot;&quot;,logs_folder:/Users/girishbenakappa/IdeaProjects/testrunner/logs/testrunner-19-Apr-26_21-18-47/test_3,spec:test" time="190.488270998"/>
	<testcase name="fts.stable_topology_fts.StableTopFTS.run_default_index_query,GROUP:P0,items:1000,upd:100,expected_hits:1000,update:True,conf_file:test.conf,num_nodes:3,cluster_name:test,expected_no_of_results:1000,ini:test.ini,case_number:4,query:&quot;&quot;&quot;{&quot;min&quot;: 1, &quot;max&quot;:1, &quot;field&quot;: &quot;mutated&quot;, &quot;inclusive_min&quot;: true, &quot;inclusive_max&quot;: true}&quot;&quot;&quot;,logs_folder:/Users/girishbenakappa/IdeaProjects/testrunner/logs/testrunner-19-Apr-26_21-18-47/test_4,spec:test" time="145.959614992">
		<error type="membase.error">['Traceback (most recent call last):\n  File &quot;pytests/fts/stable_topology_fts.py&quot;, line 88, in run_default_index_query\n    expected_no_of_results=expected_no_of_results)\n  File &quot;pytests/fts/fts_base.py&quot;, line 1175, in execute_query\n    % (expected_no_of_results, doc_ids.__len__()))\nFTSException: Expected number of results: 1000, fts returned: 10\n']</error>
	</testcase>
</testsuite>
