<?xml version="1.0" ?>
<testsuite errors="1" failures="1" name="ent_backup_restore.enterprise_backup_restore_test.EnterpriseBackupRestoreTest" skip="0" tests="1" time="75.54826784133911">
	<testcase name="ent_backup_restore.enterprise_backup_restore_test.EnterpriseBackupRestoreTest.test_backup_restore_sanity,items:1000,get-cbcollect-info:False,get-couch-dbinfo:True,skip_cleanup:False,ini:test.ini,cluster_name:test,spec:test,conf_file:test.conf,get-logs:False,stop-on-failure:False,index_type:scorch,fts_quota:750,num_nodes:4,case_number:1,logs_folder:/Users/girishbenakappa/IdeaProjects/testrunner/logs/testrunner-20-Apr-09_12-04-16/test_1" time="75.54826784133911">
		<error type="membase.error">['Traceback (most recent call last):\n  File &quot;pytests/ent_backup_restore/enterprise_backup_restore_test.py&quot;, line 92, in test_backup_restore_sanity\n    self.backup_create_validate()\n  File &quot;pytests/ent_backup_restore/enterprise_backup_restore_base.py&quot;, line 438, in backup_create_validate\n    self.fail(msg)\nAssertionError: Extra elements found in the actual Backup Meta data json. Extra elements: {\'include_data_v2\': [None], \'exclude_data_v2\': [None]}Expected elements not found in the actual Backup Meta data json. Missing elements: {\'exclude_collections\': {\'expected\': [[]]}}\n']</error>
	</testcase>
</testsuite>
