<?xml version="1.0" ?>
<testsuite errors="1" failures="1" name="tuqquery.flex_index_phase1.FlexIndexTests" skip="0" tests="1" time="818.9848818778992">
	<testcase name="tuqquery.flex_index_phase1.FlexIndexTests.test_use_index_hint,test_name:fts_index_exists,GROUP:PS,get-logs:False,stop-on-failure:False,doc-per-day:6,bucket_size:200,scan_consistency:NOT_BOUNDED,skip_load:True,items:1000,custom_map:True,cm_id:0,num_queries:100,compare_es:True,get-cbcollect-info:False,disable_HTP:True,cluster:D+F,index_type:scorch,fts_quota:750,custom_map_add_non_indexed_fields:False,text_analyzer:keyword,ini:test.ini,cluster_name:test,spec:test,conf_file:test.conf,num_nodes:2,case_number:1,logs_folder:/Users/girishbenakappa/IdeaProjects/testrunner/logs/testrunner-20-Apr-22_06-45-49/test_1" time="818.9848818778992">
		<error type="membase.error">['Traceback (most recent call last):\n  File &quot;pytests/tuqquery/flex_index_phase1.py&quot;, line 143, in test_use_index_hint\n    print(self.generate_random_queries(index))\n  File &quot;pytests/tuqquery/flex_index_phase1.py&quot;, line 129, in generate_random_queries\n    fields=index.smart_query_fields)\n  File &quot;pytests/fts/random_query_generator/rand_query_gen.py&quot;, line 914, in __init__\n    self.construct_flex_queries()\n  File &quot;pytests/fts/random_query_generator/rand_query_gen.py&quot;, line 948, in construct_flex_queries\n    self.fts_flex_queries.append(self.replace_underscores(self.fts_flex_query_template.format(predicate)))\nKeyError: \'fts_index_name\'\n']</error>
	</testcase>
</testsuite>
