<?xml version="1.0" ?>
<testsuite errors="5" failures="5" name="tuqquery.flex_index_phase1.FlexIndexTests" skip="0" tests="5" time="359.18398213386536">
	<testcase name="tuqquery.flex_index_phase1.FlexIndexTests.test_flex_single_typemapping_comp_ops,test_name:fts_index_exists,GROUP:PS,get-logs:False,stop-on-failure:False,doc-per-day:6,bucket_size:200,scan_consistency:NOT_BOUNDED,skip_load:True,items:1000,custom_map:True,get-cbcollect-info:False,disable_HTP:True,cluster:D+F,index_type:scorch,fts_quota:750,custom_map_add_non_indexed_fields:False,text_analyzer:keyword,ini:test.ini,cluster_name:test,spec:test,conf_file:test.conf,num_nodes:1,case_number:1,logs_folder:/Users/girishbenakappa/IdeaProjects/testrunner/logs/testrunner-20-Apr-23_10-35-57/test_1" time="203.92771196365356">
		<error type="membase.error">['Traceback (most recent call last):\n  File &quot;pytests/tuqquery/flex_index_phase1.py&quot;, line 203, in test_flex_single_typemapping_comp_ops\n    .format(failed_to_run_query, not_found_index_in_response, result_mismatch))\nAssertionError: Found queries not runnable: [19, 20, 21, 22, 23] or required index not found in the query resonse: [] or flex query and gsi query results not matching: [3, 4, 5, 6, 8, 10, 11, 14, 15, 16, 17, 18, 24, 25, 26, 27, 28, 39, 40, 41, 42, 43, 44]\n']</error>
	</testcase>
	<testcase name="tuqquery.flex_index_phase1.FlexIndexTests.test_flex_single_typemapping_comp_ops,test_name:fts_index_exists,GROUP:PS,get-logs:False,stop-on-failure:False,doc-per-day:6,bucket_size:200,scan_consistency:NOT_BOUNDED,skip_load:True,items:1000,custom_map:True,get-cbcollect-info:False,disable_HTP:True,cluster:D+F,index_type:scorch,fts_quota:750,custom_map_add_non_indexed_fields:False,text_analyzer:keyword,cm_id:1,ini:test.ini,cluster_name:test,spec:test,conf_file:test.conf,num_nodes:1,case_number:2,logs_folder:/Users/girishbenakappa/IdeaProjects/testrunner/logs/testrunner-20-Apr-23_10-35-57/test_2" time="40.60288906097412">
		<error type="membase.error">['Traceback (most recent call last):\n  File &quot;pytests/tuqquery/flex_index_phase1.py&quot;, line 196, in test_flex_single_typemapping_comp_ops\n    self.run_cbq_query(&quot;create primary index primary_gsi_index on default&quot;)\n  File &quot;pytests/tuqquery/tuq.py&quot;, line 1104, in run_cbq_query\n    raise CBQError(result, server.ip)\nmembase.api.exception.CBQError: CBQError: host 192.168.10.11: ERROR:{\'requestID\': \'5d7e486d-f3c5-4473-ab5c-d7adf204e012\', \'signature\': None, \'results\': [], \'errors\': [{\'code\': 5000, \'msg\': \'GSI CreatePrimaryIndex() - cause: Index primary_gsi_index already exists.\'}], \'status\': \'errors\', \'metrics\': {\'elapsedTime\': \'3.773103ms\', \'executionTime\': \'3.721035ms\', \'resultCount\': 0, \'resultSize\': 0, \'errorCount\': 1}}\n']</error>
	</testcase>
	<testcase name="tuqquery.flex_index_phase1.FlexIndexTests.test_flex_single_typemapping_comp_ops,test_name:fts_index_exists,GROUP:PS,get-logs:False,stop-on-failure:False,doc-per-day:6,bucket_size:200,scan_consistency:NOT_BOUNDED,skip_load:True,items:1000,custom_map:True,get-cbcollect-info:False,disable_HTP:True,cluster:D+F,index_type:scorch,fts_quota:750,custom_map_add_non_indexed_fields:False,text_analyzer:keyword,cm_id:2,ini:test.ini,cluster_name:test,spec:test,conf_file:test.conf,num_nodes:1,case_number:3,logs_folder:/Users/girishbenakappa/IdeaProjects/testrunner/logs/testrunner-20-Apr-23_10-35-57/test_3" time="37.98607110977173">
		<error type="membase.error">['Traceback (most recent call last):\n  File &quot;pytests/tuqquery/flex_index_phase1.py&quot;, line 196, in test_flex_single_typemapping_comp_ops\n    self.run_cbq_query(&quot;create primary index primary_gsi_index on default&quot;)\n  File &quot;pytests/tuqquery/tuq.py&quot;, line 1104, in run_cbq_query\n    raise CBQError(result, server.ip)\nmembase.api.exception.CBQError: CBQError: host 192.168.10.11: ERROR:{\'requestID\': \'c96b29c7-05ca-44a7-bfe6-72eb9adeff99\', \'signature\': None, \'results\': [], \'errors\': [{\'code\': 5000, \'msg\': \'GSI CreatePrimaryIndex() - cause: Index primary_gsi_index already exists.\'}], \'status\': \'errors\', \'metrics\': {\'elapsedTime\': \'1.161578ms\', \'executionTime\': \'1.143658ms\', \'resultCount\': 0, \'resultSize\': 0, \'errorCount\': 1}}\n']</error>
	</testcase>
	<testcase name="tuqquery.flex_index_phase1.FlexIndexTests.test_flex_single_typemapping_comp_ops,test_name:fts_index_exists,GROUP:PS,get-logs:False,stop-on-failure:False,doc-per-day:6,bucket_size:200,scan_consistency:NOT_BOUNDED,skip_load:True,items:1000,custom_map:True,get-cbcollect-info:False,disable_HTP:True,cluster:D+F,index_type:scorch,fts_quota:750,custom_map_add_non_indexed_fields:False,text_analyzer:keyword,cm_id:3,ini:test.ini,cluster_name:test,spec:test,conf_file:test.conf,num_nodes:1,case_number:4,logs_folder:/Users/girishbenakappa/IdeaProjects/testrunner/logs/testrunner-20-Apr-23_10-35-57/test_4" time="38.033774852752686">
		<error type="membase.error">['Traceback (most recent call last):\n  File &quot;pytests/tuqquery/flex_index_phase1.py&quot;, line 196, in test_flex_single_typemapping_comp_ops\n    self.run_cbq_query(&quot;create primary index primary_gsi_index on default&quot;)\n  File &quot;pytests/tuqquery/tuq.py&quot;, line 1104, in run_cbq_query\n    raise CBQError(result, server.ip)\nmembase.api.exception.CBQError: CBQError: host 192.168.10.11: ERROR:{\'requestID\': \'54bd928b-47e6-4221-8027-19b5fcb4bdc5\', \'signature\': None, \'results\': [], \'errors\': [{\'code\': 5000, \'msg\': \'GSI CreatePrimaryIndex() - cause: Index primary_gsi_index already exists.\'}], \'status\': \'errors\', \'metrics\': {\'elapsedTime\': \'1.095353ms\', \'executionTime\': \'1.078015ms\', \'resultCount\': 0, \'resultSize\': 0, \'errorCount\': 1}}\n']</error>
	</testcase>
	<testcase name="tuqquery.flex_index_phase1.FlexIndexTests.test_flex_single_typemapping_comp_ops,test_name:fts_index_exists,GROUP:PS,get-logs:False,stop-on-failure:False,doc-per-day:6,bucket_size:200,scan_consistency:NOT_BOUNDED,skip_load:True,items:1000,custom_map:True,get-cbcollect-info:False,disable_HTP:True,cluster:D+F,index_type:scorch,fts_quota:750,custom_map_add_non_indexed_fields:False,text_analyzer:keyword,cm_id:4,ini:test.ini,cluster_name:test,spec:test,conf_file:test.conf,num_nodes:1,case_number:5,logs_folder:/Users/girishbenakappa/IdeaProjects/testrunner/logs/testrunner-20-Apr-23_10-35-57/test_5" time="38.63353514671326">
		<error type="membase.error">['Traceback (most recent call last):\n  File &quot;pytests/tuqquery/flex_index_phase1.py&quot;, line 196, in test_flex_single_typemapping_comp_ops\n    self.run_cbq_query(&quot;create primary index primary_gsi_index on default&quot;)\n  File &quot;pytests/tuqquery/tuq.py&quot;, line 1104, in run_cbq_query\n    raise CBQError(result, server.ip)\nmembase.api.exception.CBQError: CBQError: host 192.168.10.11: ERROR:{\'requestID\': \'e223cd6a-62a8-4c8d-8dcb-6c72cc8c9e2e\', \'signature\': None, \'results\': [], \'errors\': [{\'code\': 5000, \'msg\': \'GSI CreatePrimaryIndex() - cause: Index primary_gsi_index already exists.\'}], \'status\': \'errors\', \'metrics\': {\'elapsedTime\': \'1.281046ms\', \'executionTime\': \'1.259088ms\', \'resultCount\': 0, \'resultSize\': 0, \'errorCount\': 1}}\n']</error>
	</testcase>
</testsuite>
