<?xml version="1.0" ?>
<testsuite errors="5" failures="5" name="tuqquery.flex_index_phase1.FlexIndexTests" skip="0" tests="5" time="608.5356993675232">
	<testcase name="tuqquery.flex_index_phase1.FlexIndexTests.test_flex_single_typemapping_comp_ops,test_name:fts_index_exists,GROUP:PS,get-logs:False,stop-on-failure:False,doc-per-day:6,bucket_size:200,scan_consistency:NOT_BOUNDED,skip_load:True,items:1000,custom_map:True,get-cbcollect-info:False,disable_HTP:True,cluster:D+F,index_type:scorch,fts_quota:750,custom_map_add_non_indexed_fields:False,text_analyzer:keyword,ini:test.ini,cluster_name:test,spec:test,conf_file:test.conf,num_nodes:1,case_number:1,logs_folder:/Users/girishbenakappa/IdeaProjects/testrunner/logs/testrunner-20-Apr-23_13-44-44/test_1" time="190.27758502960205">
		<error type="membase.error">['Traceback (most recent call last):\n  File &quot;pytests/tuqquery/flex_index_phase1.py&quot;, line 204, in test_flex_single_typemapping_comp_ops\n    .format(failed_to_run_query, not_found_index_in_response, result_mismatch))\nAssertionError: Found queries not runnable: [46, 47, 48, 49, 50] or required index not found in the query resonse: [3] or flex query and gsi query results not matching: [4, 7, 19, 20, 21, 22, 24, 25, 26, 27, 33, 37, 38, 39, 41, 42, 43, 44, 45]\n']</error>
	</testcase>
	<testcase name="tuqquery.flex_index_phase1.FlexIndexTests.test_flex_single_typemapping_comp_ops,test_name:fts_index_exists,GROUP:PS,get-logs:False,stop-on-failure:False,doc-per-day:6,bucket_size:200,scan_consistency:NOT_BOUNDED,skip_load:True,items:1000,custom_map:True,get-cbcollect-info:False,disable_HTP:True,cluster:D+F,index_type:scorch,fts_quota:750,custom_map_add_non_indexed_fields:False,text_analyzer:keyword,cm_id:1,ini:test.ini,cluster_name:test,spec:test,conf_file:test.conf,num_nodes:1,case_number:2,logs_folder:/Users/girishbenakappa/IdeaProjects/testrunner/logs/testrunner-20-Apr-23_13-44-44/test_2" time="292.8669271469116">
		<error type="membase.error">['Traceback (most recent call last):\n  File &quot;pytests/tuqquery/flex_index_phase1.py&quot;, line 204, in test_flex_single_typemapping_comp_ops\n    .format(failed_to_run_query, not_found_index_in_response, result_mismatch))\nAssertionError: Found queries not runnable: [24, 25, 26, 27, 28] or required index not found in the query resonse: [] or flex query and gsi query results not matching: [1, 2, 3, 4, 5, 11, 12, 13, 14, 16, 17, 18, 19, 20, 21, 22, 23]\n']</error>
	</testcase>
	<testcase name="tuqquery.flex_index_phase1.FlexIndexTests.test_flex_single_typemapping_comp_ops,test_name:fts_index_exists,GROUP:PS,get-logs:False,stop-on-failure:False,doc-per-day:6,bucket_size:200,scan_consistency:NOT_BOUNDED,skip_load:True,items:1000,custom_map:True,get-cbcollect-info:False,disable_HTP:True,cluster:D+F,index_type:scorch,fts_quota:750,custom_map_add_non_indexed_fields:False,text_analyzer:keyword,cm_id:2,ini:test.ini,cluster_name:test,spec:test,conf_file:test.conf,num_nodes:1,case_number:3,logs_folder:/Users/girishbenakappa/IdeaProjects/testrunner/logs/testrunner-20-Apr-23_13-44-44/test_3" time="40.79331707954407">
		<error type="membase.error">['Traceback (most recent call last):\n  File &quot;pytests/tuqquery/flex_index_phase1.py&quot;, line 204, in test_flex_single_typemapping_comp_ops\n    .format(failed_to_run_query, not_found_index_in_response, result_mismatch))\nAssertionError: Found queries not runnable: [] or required index not found in the query resonse: [] or flex query and gsi query results not matching: [6, 7, 8, 9, 11, 13, 15, 16, 17, 18, 19]\n']</error>
	</testcase>
	<testcase name="tuqquery.flex_index_phase1.FlexIndexTests.test_flex_single_typemapping_comp_ops,test_name:fts_index_exists,GROUP:PS,get-logs:False,stop-on-failure:False,doc-per-day:6,bucket_size:200,scan_consistency:NOT_BOUNDED,skip_load:True,items:1000,custom_map:True,get-cbcollect-info:False,disable_HTP:True,cluster:D+F,index_type:scorch,fts_quota:750,custom_map_add_non_indexed_fields:False,text_analyzer:keyword,cm_id:3,ini:test.ini,cluster_name:test,spec:test,conf_file:test.conf,num_nodes:1,case_number:4,logs_folder:/Users/girishbenakappa/IdeaProjects/testrunner/logs/testrunner-20-Apr-23_13-44-44/test_4" time="43.161882162094116">
		<error type="membase.error">['Traceback (most recent call last):\n  File &quot;pytests/tuqquery/flex_index_phase1.py&quot;, line 204, in test_flex_single_typemapping_comp_ops\n    .format(failed_to_run_query, not_found_index_in_response, result_mismatch))\nAssertionError: Found queries not runnable: [] or required index not found in the query resonse: [35, 36, 37, 38, 39] or flex query and gsi query results not matching: [1, 2, 3, 4, 5, 40, 41, 42, 43]\n']</error>
	</testcase>
	<testcase name="tuqquery.flex_index_phase1.FlexIndexTests.test_flex_single_typemapping_comp_ops,test_name:fts_index_exists,GROUP:PS,get-logs:False,stop-on-failure:False,doc-per-day:6,bucket_size:200,scan_consistency:NOT_BOUNDED,skip_load:True,items:1000,custom_map:True,get-cbcollect-info:False,disable_HTP:True,cluster:D+F,index_type:scorch,fts_quota:750,custom_map_add_non_indexed_fields:False,text_analyzer:keyword,cm_id:4,ini:test.ini,cluster_name:test,spec:test,conf_file:test.conf,num_nodes:1,case_number:5,logs_folder:/Users/girishbenakappa/IdeaProjects/testrunner/logs/testrunner-20-Apr-23_13-44-44/test_5" time="41.43598794937134">
		<error type="membase.error">['Traceback (most recent call last):\n  File &quot;pytests/tuqquery/flex_index_phase1.py&quot;, line 204, in test_flex_single_typemapping_comp_ops\n    .format(failed_to_run_query, not_found_index_in_response, result_mismatch))\nAssertionError: Found queries not runnable: [32, 33, 34, 35, 36] or required index not found in the query resonse: [3, 13] or flex query and gsi query results not matching: [9, 10, 11, 14, 15, 16, 17, 19, 20, 21, 27, 28, 29, 30, 31]\n']</error>
	</testcase>
</testsuite>
