<?xml version="1.0" ?>
<testsuite errors="1" failures="1" name="tuqquery.n1ql_fts_integration.N1qlFTSIntegrationTest" skip="0" tests="1" time="833.030599117">
	<testcase name="tuqquery.n1ql_fts_integration.N1qlFTSIntegrationTest.test_clusterops_fts_node_failover,doc-per-day:1,GROUP:P1,spec:test,reset_services:True,num_nodes:3,cluster_name:test,services_init:kv:index:n1ql-fts-fts:n1ql:index,conf_file:test.conf,case_number:1,get-logs:False,stop-on-failure:False,scan_consistency:NOT_BOUNDED,logs_folder:/Users/girishbenakappa/IdeaProjects/testrunner/logs/testrunner-19-Sep-17_13-41-32/test_1,bucket_size:200,nodes_init:3,ini:test.ini" time="833.030599117">
		<error type="membase.error">['Traceback (most recent call last):\n  File &quot;pytests/tuqquery/n1ql_fts_integration.py&quot;, line 543, in test_clusterops_fts_node_failover\n    idx_result_node1_after_failover = self._run_query_against_node(self.servers[0], self.test_fts_query)\n  File &quot;pytests/tuqquery/n1ql_fts_integration.py&quot;, line 699, in _run_query_against_node\n    fts_result = self.run_cbq_query(query=fts_query, server=node, username=username, password=password)\n  File &quot;pytests/tuqquery/tuq.py&quot;, line 1078, in run_cbq_query\n    raise CBQError(result, server.ip)\nCBQError: CBQError: host 172.23.109.172: ERROR:{u\'status\': u\'errors\', u\'errors\': [{u\'msg\': u\' dial tcp 172.23.109.180:9101: connect: connection refused from [172.23.109.180:9101] - cause:  dial tcp 172.23.109.180:9101: connect: connection refused from [172.23.109.180:9101]\', u\'code\': 5000}], u\'results\': [], u\'metrics\': {u\'elapsedTime\': u\'46.889039ms\', u\'executionTime\': u\'46.833206ms\', u\'resultSize\': 0, u\'resultCount\': 0, u\'errorCount\': 1}, u\'requestID\': u\'8e6e0b82-8a7b-41e8-a5ba-992e82e55362\', u\'signature\': {u\'primary_key\': u\'json\'}}\n']</error>
	</testcase>
</testsuite>
