<?xml version="1.0" ?>
<testsuite errors="1" failures="1" name="fts.moving_topology_fts.MovingTopFTS" skip="0" tests="1" time="242.571680069">
	<testcase name="fts.moving_topology_fts.MovingTopFTS.failover_no_rebalance_with_replicas_between_indexing_and_querying,num_queries:20,logs_folder:/Users/girishbenakappa/IdeaProjects/testrunner/logs/testrunner-20-Apr-08_10-33-32/test_1,GROUP:P1,compare_es:True,index_type:scorch,items:20000,fts_quota:750,conf_file:test.conf,num_nodes:4,cluster_name:test,cluster:D,F,D+F,stop-on-failure:False,ini:test.ini,case_number:1,get-logs:False,graceful:True,get-cbcollect-info:False,spec:test,index_replicas:1" time="242.571680069">
		<error type="membase.error">['Traceback (most recent call last):\n  File &quot;pytests/fts/moving_topology_fts.py&quot;, line 596, in failover_no_rebalance_with_replicas_between_indexing_and_querying\n    self.run_query_and_compare(index)\n  File &quot;pytests/fts/fts_base.py&quot;, line 4389, in run_query_and_compare\n    failed_queries))\nAssertionError: 16 out of 20 queries failed! - [1, 2, 3, 5, 6, 8, 9, 10, 11, 12, 13, 15, 16, 18, 19, 20]\n']</error>
	</testcase>
</testsuite>
