<?xml version="1.0" ?>
<testsuite errors="1" failures="1" name="tuqquery.n1ql_fts_integration.N1qlFTSIntegrationTest" skip="0" tests="1" time="1.68754410744">
	<testcase name="tuqquery.n1ql_fts_integration.N1qlFTSIntegrationTest.test_mixed_cluster,doc-per-day:1,GROUP:P1,spec:test,reset_services:True,num_nodes:3,cluster_name:test,services_init:kv:index:n1ql-kv-index:n1ql:fts,conf_file:test.conf,case_number:1,get-logs:False,stop-on-failure:False,scan_consistency:NOT_BOUNDED,logs_folder:/Users/girishbenakappa/IdeaProjects/testrunner/logs/testrunner-19-Aug-12_14-10-33/test_1,bucket_size:200,nodes_init:3,ini:test.ini" time="1.68754410744">
		<error type="membase.error">['Traceback (most recent call last):\n  File &quot;pytests/tuqquery/n1ql_fts_integration.py&quot;, line 268, in setUp\n    super(N1qlFTSIntegrationTest, self).setUp()\n  File &quot;pytests/tuqquery/tuq.py&quot;, line 48, in setUp\n    super(QueryTests, self).setUp()\n  File &quot;pytests/basetestcase.py&quot;, line 75, in setUp\n    shell = RemoteMachineShellConnection(self.master)\n  File &quot;lib/remote/remote_util.py&quot;, line 265, in __init__\n    exit(1)\n  File &quot;/usr/local/Cellar/python@2/2.7.16/Frameworks/Python.framework/Versions/2.7/lib/python2.7/site.py&quot;, line 351, in __call__\n    raise SystemExit(code)\nSystemExit: 1\n']</error>
	</testcase>
</testsuite>
